<mujoco model="5bar">
  <compiler angle="radian"/>

  <asset>
    <mesh name="base_link" file="base_link.STL"/>
    <mesh name="bd" file="bd.STL"/>
    <mesh name="df" file="df.STL"/>
    <mesh name="cfp_f" file="cfp_f.STL"/>
    <mesh name="ac" file="ac.STL"/>
    <mesh name="cfp_c" file="cfp_c.STL"/>
  </asset>

  <worldbody>
    <geom name="x_axis" type="cylinder" fromto="0 0 0 1 0 0" size="0.001" rgba="1 0 0 1"/>
    <geom name="y_axis" type="cylinder" fromto="0 0 0 0 1 0" size="0.001" rgba="0 1 0 1"/>
    <geom name="z_axis" type="cylinder" fromto="0 0 0 0 0 1" size="0.001" rgba="0 0 1 1"/>
    <geom type="mesh" rgba="0.792157 0.819608 0.933333 1" mesh="base_link"/>
    <body name="bd">
      <inertial pos="-0.00581349 -0.000508622 0.00385706" quat="-0.0302491 0.719801 0.0314276 0.692809" mass="0.0065" diaginertia="1.10165e-06 8.16244e-07 3.27432e-07"/>
      <joint name="1" pos="0 0 0" axis="0 0 1"/>
      <geom type="mesh" rgba="1 1 1 1" mesh="bd"/>
      <body name="df" pos="-0.026459 -0.0023149 0.0085">
        <inertial pos="-0.00699491 -0.0260919 0.00576534" quat="0.561628 0.429951 -0.560398 0.430895" mass="0.0085" diaginertia="2.5096e-06 2.43627e-06 1.39512e-07"/>
        <joint name="2" pos="0 0 0" axis="0 0 1"/>
        <geom type="mesh" rgba="1 1 1 0.32" mesh="df"/>
        <body name="cfp_f" pos="-0.014112 -0.052641 0.009">
          <inertial pos="0.000991822 -0.0371965 -0.00450308" quat="0.594658 0.382345 -0.594827 0.38259" mass="0.024" diaginertia="1.36656e-05 1.29227e-05 1.1416e-06"/>
          <joint name="3" pos="0 0 0" axis="0 0 1"/>
          <geom type="mesh" rgba="0.792157 0.819608 0.933333 1" mesh="cfp_f"/>
          <site name="endeff" size="0.002" pos="-0.05031541 -0.12513065 -0.00450033" rgba="1 0 0 1"/>
        </body>
      </body>
    </body>
    <body name="ac" pos="0.060004 -0.10393 0">
      <inertial pos="-0.0139838 0.00122344 0.00911879" quat="0.0293969 0.738096 -0.0322259 0.673285" mass="0.0135" diaginertia="4.62188e-06 4.18541e-06 6.91255e-07"/>
      <joint name="4" pos="0 0 0" axis="0 0 1"/>
      <geom type="mesh" rgba="1 1 1 0.32" mesh="ac"/>
      <body name="cfp_c" pos="-0.048315 0.0042271 0.0165">
        <inertial pos="-0.0341084 -0.00768776 -0.0035" quat="-0.250948 0.661079 0.250948 0.661079" mass="0.020" diaginertia="1.35755e-05 1.27829e-05 1.17245e-06"/>
        <joint name="5" pos="0 0 0" axis="0 0 1"/>
        <geom type="mesh" rgba="0.792157 0.819608 0.933333 1" mesh="cfp_c"/>
      </body>
    </body>
  </worldbody>

  <actuator>
    <position name="B_pos" joint="1" kp="0"/>
    <velocity name="B_vel" joint="1" kv="0"/>
    <position name="A_pos" joint="4" kp="0"/>
    <velocity name="A_vel" joint="4" kv="0"/>
  </actuator>


</mujoco>